
<?xml version="1.0" ?>
<!--
  Ignition Gazebo buoyancy plugin demo. This world contains the following
  three models:
  1. submarine: A simple submarine model that floats in place.
  2. submarine_sinking: A simple submarine model that is not buoyant and sinks.
  3. submarine_buoyant: A simple submarine model that is buoyant and floats.
  To run this demo: `ign gazebo -v 4 buoyancy.sdf`
  To alter a submarine's buoyancy do one or both of the following:
  1. Change the submarine's inertia.
  2. Change the `uniform_fluid_density` in the `buoyancy-system` plugin.
  To drive the submarine model:
  1. ign topic -t "/model/submarine/joint/propeller_joint/cmd_force" -m ignition.msgs.Double  -p "data: 1.2"
-->
<sdf version="1.6">
    <model name='submarine_buoyant'>
        <pose>-5 0 0 1.5707963267948966 0 0</pose>
        <link name='body'>
          <pose>0 0 -1.07935 0 0 0</pose>
          <inertial>
            <mass>367.5663404700058</mass>
            <inertia>
              <ixx>215.33261445867842</ixx>
              <ixy>0</ixy>
              <ixz>0</ixz>
              <iyy>215.33261445867842</iyy>
              <iyz>0</iyz>
              <izz>16.54048532115026</izz>
            </inertia>
          </inertial>
  
          <visual name='body_visual'>
            <geometry>
              <cylinder>
                <radius>0.3</radius>
                <length>2.6</length>
              </cylinder>
            </geometry>
          </visual>
          <collision name='body_collision'>
            <geometry>
              <cylinder>
                <radius>0.3</radius>
                <length>2.6</length>
              </cylinder>
            </geometry>
          </collision>
  
          <visual name='spacer_visual'>
            <pose>0 0 1.378546 0 0 0</pose>
            <geometry>
              <cylinder>
                <radius>0.0933402</radius>
                <length>0.127211</length>
              </cylinder>
            </geometry>
          </visual>
        </link>
  
        <link name='propeller'>
          <pose>0 0 0.3455 3.14159 0 0</pose>
          <inertial>
            <mass>8.410409900000001</mass>
            <inertia>
              <ixx>0.17730244606378792</ixx>
              <ixy>0</ixy>
              <ixz>0</ixz>
              <iyy>0.17730244606378792</iyy>
              <iyz>0</iyz>
              <izz>0.35043374583333337</izz>
            </inertia>
          </inertial>
  
  
          <visual name="blade1_visual">
            <pose>0.3433402 0.0 0 -0.7853981633974483 0 0.0</pose>
            <geometry>
              <box>
                <size>0.5 0.154178 0.05455</size>
              </box>
            </geometry>
          </visual>
          <collision name="blade1_collision">
            <pose>0.3433402 0.0 0 -0.7853981633974483 0 0.0</pose>
            <geometry>
              <box>
                <size>0.5 0.154178 0.05455</size>
              </box>
            </geometry>
          </collision>
  
          <visual name="blade2_visual">
            <pose>0.0 0.3433402 0 -0.7853981633974483 0 1.5707963267948966</pose>
            <geometry>
              <box>
                <size>0.5 0.154178 0.05455</size>
              </box>
            </geometry>
          </visual>
          <collision name="blade2_collision">
            <pose>0.0 0.3433402 0 -0.7853981633974483 0 1.5707963267948966</pose>
            <geometry>
              <box>
                <size>0.5 0.154178 0.05455</size>
              </box>
            </geometry>
          </collision>
  
          <visual name="blade3_visual">
            <pose>-0.3433402 -0.0 0 0.7853981633974483 0 0.0</pose>
            <geometry>
              <box>
                <size>0.5 0.154178 0.05455</size>
              </box>
            </geometry>
          </visual>
          <collision name="blade3_collision">
            <pose>-0.3433402 -0.0 0 0.7853981633974483 0 0.0</pose>
            <geometry>
              <box>
                <size>0.5 0.154178 0.05455</size>
              </box>
            </geometry>
          </collision>
  
          <visual name="blade4_visual">
            <pose>-0.0 -0.3433402 0 0.7853981633974483 0 1.5707963267948966</pose>
            <geometry>
              <box>
                <size>0.5 0.154178 0.05455</size>
              </box>
            </geometry>
          </visual>
          <collision name="blade4_collision">
            <pose>-0.0 -0.3433402 0 0.7853981633974483 0 1.5707963267948966</pose>
            <geometry>
              <box>
                <size>0.5 0.154178 0.05455</size>
              </box>
            </geometry>
          </collision>
  
        </link>
  
        <joint name='propeller_joint' type='revolute'>
          <parent>body</parent>
          <child>propeller</child>
          <axis>
            <xyz>0 0 1</xyz>
            <use_parent_model_frame>1</use_parent_model_frame>
            <limit>
              <lower>-1e+12</lower>
              <upper>1e+12</upper>
              <effort>-1</effort>
              <velocity>-1</velocity>
            </limit>
          </axis>
        </joint>
      </model>
</sdf>